{
  "comments": [
    {
      "unresolved": false,
      "key": {
        "uuid": "c6f27357_5b01537b",
        "filename": "/PATCHSET_LEVEL",
        "patchSetId": 6
      },
      "lineNbr": 0,
      "author": {
        "id": 7288
      },
      "writtenOn": "2022-02-22T20:53:45Z",
      "side": 1,
      "message": "Thank you Guillaume for your review I took into consideration your remarks in the patchset 6",
      "revId": "9740d3f5df0759a0c2a0589a3c3c0dab95bf6ce6",
      "serverId": "7fc14799-209e-464c-9743-7a06c2c21a81"
    },
    {
      "unresolved": false,
      "key": {
        "uuid": "07d15859_3410c361",
        "filename": "/PATCHSET_LEVEL",
        "patchSetId": 6
      },
      "lineNbr": 0,
      "author": {
        "id": 6731
      },
      "writtenOn": "2022-02-22T22:11:02Z",
      "side": 1,
      "message": "Junit did not pass\n\n16:35:30 [ERROR] Tests run: 2, Failures: 1, Errors: 0, Skipped: 0, Time elapsed: 0.339 s \u003c\u003c\u003c FAILURE! - in org.opendaylight.transportpce.common.converter.JsonStringConverterTest\n16:35:30 [ERROR] createJsonStringFromDataObjectTest(org.opendaylight.transportpce.common.converter.JsonStringConverterTest)  Time elapsed: 0.293 s  \u003c\u003c\u003c FAILURE!",
      "revId": "9740d3f5df0759a0c2a0589a3c3c0dab95bf6ce6",
      "serverId": "7fc14799-209e-464c-9743-7a06c2c21a81"
    },
    {
      "unresolved": false,
      "key": {
        "uuid": "1de8e628_2bddef59",
        "filename": "/PATCHSET_LEVEL",
        "patchSetId": 6
      },
      "lineNbr": 0,
      "author": {
        "id": 6731
      },
      "writtenOn": "2022-02-22T22:11:02Z",
      "side": 1,
      "message": "You\u0027re welcome.\nI think some of them are still pending.",
      "parentUuid": "c6f27357_5b01537b",
      "revId": "9740d3f5df0759a0c2a0589a3c3c0dab95bf6ce6",
      "serverId": "7fc14799-209e-464c-9743-7a06c2c21a81"
    },
    {
      "unresolved": false,
      "key": {
        "uuid": "6208a73a_88e0c2ca",
        "filename": "/PATCHSET_LEVEL",
        "patchSetId": 6
      },
      "lineNbr": 0,
      "author": {
        "id": 6731
      },
      "writtenOn": "2022-02-23T11:42:43Z",
      "side": 1,
      "message": "FYI got an issue locally with python3.9\n\ntestsPCE develop-inst-noop: /home/guillaume/git_ws/transportpce/tests\ntestsPCE installed: certifi\u003d\u003d2021.10.8,cffi\u003d\u003d1.15.0,charset-normalizer\u003d\u003d2.0.12,click\u003d\u003d8.0.4,cryptography\u003d\u003d3.3.2,cycler\u003d\u003d0.11.0,Flask\u003d\u003d2.0.3,Flask-Injector\u003d\u003d0.13.0,fonttools\u003d\u003d4.29.1,gnpy4tpce\u003d\u003d2.4.2,idna\u003d\u003d3.3,injector\u003d\u003d0.19.0,itsdangerous\u003d\u003d2.1.0,Jinja2\u003d\u003d3.0.3,kiwisolver\u003d\u003d1.3.2,MarkupSafe\u003d\u003d2.1.0,matplotlib\u003d\u003d3.5.1,networkx\u003d\u003d2.6.3,nose\u003d\u003d1.3.7,numpy\u003d\u003d1.22.2,packaging\u003d\u003d21.3,pandas\u003d\u003d1.4.1,pbr\u003d\u003d5.8.1,Pillow\u003d\u003d9.0.1,psutil\u003d\u003d5.9.0,pycparser\u003d\u003d2.21,pyparsing\u003d\u003d3.0.7,python-dateutil\u003d\u003d2.8.2,pytz\u003d\u003d2021.3,requests\u003d\u003d2.27.1,scipy\u003d\u003d1.8.0,six\u003d\u003d1.16.0,-e git+ssh://guillaume.lambert@git.opendaylight.org:29418/transportpce@9740d3f5df0759a0c2a0589a3c3c0dab95bf6ce6#egg\u003dtransportpce_tests\u0026subdirectory\u003dtests,urllib3\u003d\u003d1.26.8,Werkzeug\u003d\u003d2.0.3,xlrd\u003d\u003d1.2.0\ntestsPCE run-test-pre: PYTHONHASHSEED\u003d\u00273381533145\u0027\ntestsPCE run-test: commands[0] | ./launch_tests.sh pce gnpy\nnosetests --with-xunit transportpce_tests/pce/test03_gnpy.py\n......F.....\n\u003d\u003d\u003d\u003d\u003d\u003d\u003d\u003d\u003d\u003d\u003d\u003d\u003d\u003d\u003d\u003d\u003d\u003d\u003d\u003d\u003d\u003d\u003d\u003d\u003d\u003d\u003d\u003d\u003d\u003d\u003d\u003d\u003d\u003d\u003d\u003d\u003d\u003d\u003d\u003d\u003d\u003d\u003d\u003d\u003d\u003d\u003d\u003d\u003d\u003d\u003d\u003d\u003d\u003d\u003d\u003d\u003d\u003d\u003d\u003d\u003d\u003d\u003d\u003d\u003d\u003d\u003d\u003d\u003d\u003d\nFAIL: test_06_path_computation_NotFoundByPCE_FoundByGNPy (test03_gnpy.TransportGNPYtesting)\n----------------------------------------------------------------------\nTraceback (most recent call last):\n  File \"/home/guillaume/git_ws/transportpce/tests/transportpce_tests/pce/test03_gnpy.py\", line 181, in test_06_path_computation_NotFoundByPCE_FoundByGNPy\n    self.assertEqual(res[\u0027output\u0027][\u0027configuration-response-common\u0027][\nAssertionError: \u0027500\u0027 !\u003d \u0027200\u0027\n- 500\n? ^\n+ 200\n? ^\n\n-------------------- \u003e\u003e begin captured stdout \u003c\u003c ---------------------\n{\"input\": {\"service-name\": \"service-3\", \"resource-reserve\": \"true\", \"service-handler-header\": {\"request-id\": \"request-3\"}, \"service-a-end\": {\"node-id\": \"XPONDER-1\", \"service-rate\": \"100\", \"service-format\": \"Ethernet\", \"clli\": \"Node1\"}, \"service-z-end\": {\"node-id\": \"XPONDER-4\", \"service-rate\": \"100\", \"service-format\": \"Ethernet\", \"clli\": \"Node5\"}, \"pce-metric\": \"hop-count\", \"hard-constraints\": {\"include_\": {\"ordered-hops\": [{\"hop-number\": \"0\", \"hop-type\": {\"node-id\": \"OpenROADM-2\"}}, {\"hop-number\": \"1\", \"hop-type\": {\"node-id\": \"OpenROADM-3\"}}]}}}}\n\n--------------------- \u003e\u003e end captured stdout \u003c\u003c ----------------------\n-------------------- \u003e\u003e begin captured logging \u003c\u003c --------------------\nurllib3.connectionpool: DEBUG: Starting new HTTP connection (1): localhost:8181\nurllib3.connectionpool: DEBUG: http://localhost:8181 \"POST /restconf/operations/transportpce-pce:path-computation-request HTTP/1.1\" 200 160\n--------------------- \u003e\u003e end captured logging \u003c\u003c ---------------------\n\n----------------------------------------------------------------------\nRan 12 tests in 87.404s\n\nFAILED (failures\u003d1)\nERROR: InvocationError for command /home/guillaume/git_ws/transportpce/tests/launch_tests.sh pce gnpy (exited with code 1)\n__________________________________________________________________________________________________________________ summary ___________________________________________________________________________________________________________________\n  buildcontroller: commands succeeded\nERROR:   testsPCE: commands failed\n",
      "revId": "9740d3f5df0759a0c2a0589a3c3c0dab95bf6ce6",
      "serverId": "7fc14799-209e-464c-9743-7a06c2c21a81"
    },
    {
      "unresolved": false,
      "key": {
        "uuid": "e22e25ad_fb61a4ec",
        "filename": "/PATCHSET_LEVEL",
        "patchSetId": 6
      },
      "lineNbr": 0,
      "author": {
        "id": 6731
      },
      "writtenOn": "2022-02-23T12:03:52Z",
      "side": 1,
      "message": "Same issue with python 3.8.10\nplease can you specify a minimal version\n\n$ python3 --version\nPython 3.8.10\n\n$tox -e testsPCE gnpy\ntestsPCE recreate: /home/lambergu/transportpce/.tox/testsPCE\ntestsPCE installdeps: -r/home/lambergu/transportpce/tests/requirements.txt, -r/home/lambergu/transportpce/tests/test-requirements.txt, setuptools\u003e\u003d7.0, gnpy4tpce\u003d\u003d2.4.2\ntestsPCE develop-inst: /home/lambergu/transportpce/tests\ntestsPCE installed: certifi\u003d\u003d2021.10.8,cffi\u003d\u003d1.15.0,charset-normalizer\u003d\u003d2.0.12,click\u003d\u003d8.0.4,cryptography\u003d\u003d3.3.2,cycler\u003d\u003d0.11.0,Flask\u003d\u003d2.0.3,Flask-Injector\u003d\u003d0.13.0,fonttools\u003d\u003d4.29.1,gnpy4tpce\u003d\u003d2.4.2,idna\u003d\u003d3.3,injector\u003d\u003d0.19.0,itsdangerous\u003d\u003d2.1.0,Jinja2\u003d\u003d3.0.3,kiwisolver\u003d\u003d1.3.2,MarkupSafe\u003d\u003d2.1.0,matplotlib\u003d\u003d3.5.1,networkx\u003d\u003d2.6.3,nose\u003d\u003d1.3.7,numpy\u003d\u003d1.22.2,packaging\u003d\u003d21.3,pandas\u003d\u003d1.4.1,pbr\u003d\u003d5.8.1,Pillow\u003d\u003d9.0.1,psutil\u003d\u003d5.9.0,pycparser\u003d\u003d2.21,pyparsing\u003d\u003d3.0.7,python-dateutil\u003d\u003d2.8.2,pytz\u003d\u003d2021.3,requests\u003d\u003d2.27.1,scipy\u003d\u003d1.8.0,six\u003d\u003d1.16.0,-e git+ssh://guillaume.lambert@git.opendaylight.org:29418/transportpce@9740d3f5df0759a0c2a0589a3c3c0dab95bf6ce6#egg\u003dtransportpce_tests\u0026subdirectory\u003dtests,typing-extensions\u003d\u003d4.1.1,urllib3\u003d\u003d1.26.8,Werkzeug\u003d\u003d2.0.3,xlrd\u003d\u003d1.2.0\ntestsPCE run-test-pre: PYTHONHASHSEED\u003d\u00271720357804\u0027\ntestsPCE run-test: commands[0] | ./launch_tests.sh pce gnpy\nnosetests --with-xunit transportpce_tests/pce/test03_gnpy.py\n......F.....\n\u003d\u003d\u003d\u003d\u003d\u003d\u003d\u003d\u003d\u003d\u003d\u003d\u003d\u003d\u003d\u003d\u003d\u003d\u003d\u003d\u003d\u003d\u003d\u003d\u003d\u003d\u003d\u003d\u003d\u003d\u003d\u003d\u003d\u003d\u003d\u003d\u003d\u003d\u003d\u003d\u003d\u003d\u003d\u003d\u003d\u003d\u003d\u003d\u003d\u003d\u003d\u003d\u003d\u003d\u003d\u003d\u003d\u003d\u003d\u003d\u003d\u003d\u003d\u003d\u003d\u003d\u003d\u003d\u003d\u003d\nFAIL: test_06_path_computation_NotFoundByPCE_FoundByGNPy (test03_gnpy.TransportGNPYtesting)\n----------------------------------------------------------------------\nTraceback (most recent call last):\n  File \"/home/lambergu/transportpce/tests/transportpce_tests/pce/test03_gnpy.py\", line 181, in test_06_path_computation_NotFoundByPCE_FoundByGNPy\n    self.assertEqual(res[\u0027output\u0027][\u0027configuration-response-common\u0027][\nAssertionError: \u0027500\u0027 !\u003d \u0027200\u0027\n- 500\n? ^\n+ 200\n? ^\n\n-------------------- \u003e\u003e begin captured stdout \u003c\u003c ---------------------\n{\"input\": {\"service-name\": \"service-3\", \"resource-reserve\": \"true\", \"service-handler-header\": {\"request-id\": \"request-3\"}, \"service-a-end\": {\"node-id\": \"XPONDER-1\", \"service-rate\": \"100\", \"service-format\": \"Ethernet\", \"clli\": \"Node1\"}, \"service-z-end\": {\"node-id\": \"XPONDER-4\", \"service-rate\": \"100\", \"service-format\": \"Ethernet\", \"clli\": \"Node5\"}, \"pce-metric\": \"hop-count\", \"hard-constraints\": {\"include_\": {\"ordered-hops\": [{\"hop-number\": \"0\", \"hop-type\": {\"node-id\": \"OpenROADM-2\"}}, {\"hop-number\": \"1\", \"hop-type\": {\"node-id\": \"OpenROADM-3\"}}]}}}}\n\n--------------------- \u003e\u003e end captured stdout \u003c\u003c ----------------------\n-------------------- \u003e\u003e begin captured logging \u003c\u003c --------------------\nurllib3.connectionpool: DEBUG: Starting new HTTP connection (1): localhost:8181\nurllib3.connectionpool: DEBUG: http://localhost:8181 \"POST /restconf/operations/transportpce-pce:path-computation-request HTTP/1.1\" 200 160\n--------------------- \u003e\u003e end captured logging \u003c\u003c ---------------------\n\n----------------------------------------------------------------------\nRan 12 tests in 97.338s\n\nFAILED (failures\u003d1)\nERROR: InvocationError for command /home/lambergu/transportpce/tests/launch_tests.sh pce gnpy (exited with code 1)\n__________________________________________________________________________________________________________________ summary ___________________________________________________________________________________________________________________\nERROR:   testsPCE: commands failed",
      "parentUuid": "6208a73a_88e0c2ca",
      "revId": "9740d3f5df0759a0c2a0589a3c3c0dab95bf6ce6",
      "serverId": "7fc14799-209e-464c-9743-7a06c2c21a81"
    }
  ]
}